<mujoco model="chitrak_description">
  <compiler angle="radian"/>

  <asset>
    <mesh name="torso_link" content_type="model/stl" file="/home/aaditya/Desktop/chitrak/chitrak_description/meshes/torso_link.STL"/>
    <mesh name="fr_hip_link" content_type="model/stl" file="/home/aaditya/Desktop/chitrak/chitrak_description/meshes/fr_hip_link.STL"/>
    <mesh name="fr_thigh_link" content_type="model/stl" file="/home/aaditya/Desktop/chitrak/chitrak_description/meshes/fr_thigh_link.STL"/>
    <mesh name="fr_calf_link" content_type="model/stl" file="/home/aaditya/Desktop/chitrak/chitrak_description/meshes/fr_calf_link.STL"/>
    <mesh name="fl_hip_link" content_type="model/stl" file="/home/aaditya/Desktop/chitrak/chitrak_description/meshes/fl_hip_link.STL"/>
    <mesh name="fl_thigh_link" content_type="model/stl" file="/home/aaditya/Desktop/chitrak/chitrak_description/meshes/fl_thigh_link.STL"/>
    <mesh name="fl_calf_link" content_type="model/stl" file="/home/aaditya/Desktop/chitrak/chitrak_description/meshes/fl_calf_link.STL"/>
    <mesh name="br_hip_link" content_type="model/stl" file="/home/aaditya/Desktop/chitrak/chitrak_description/meshes/br_hip_link.STL"/>
    <mesh name="br_thigh_link" content_type="model/stl" file="/home/aaditya/Desktop/chitrak/chitrak_description/meshes/br_thigh_link.STL"/>
    <mesh name="br_calf_link" content_type="model/stl" file="/home/aaditya/Desktop/chitrak/chitrak_description/meshes/br_calf_link.STL"/>
    <mesh name="bl_hip_link" content_type="model/stl" file="/home/aaditya/Desktop/chitrak/chitrak_description/meshes/bl_hip_link.STL"/>
    <mesh name="bl_thigh_link" content_type="model/stl" file="/home/aaditya/Desktop/chitrak/chitrak_description/meshes/bl_thigh_link.STL"/>
    <mesh name="bl_calf_link" content_type="model/stl" file="/home/aaditya/Desktop/chitrak/chitrak_description/meshes/bl_calf_link.STL"/>
  </asset>

  <worldbody>
    <geom type="mesh" rgba="0.752941 0.752941 0.752941 1" mesh="torso_link"/>
    <body name="fr_hip_link" pos="0.1034 -0.0557689 -0.018465">
      <inertial pos="0.0322826 -0.000429461 -0.0140006" quat="0.501642 0.496046 0.503748 0.49853" mass="0.108649" diaginertia="4.61686e-05 4.28729e-05 2.69799e-05"/>
      <joint name="fr_hip_roll_joint" pos="0 0 0" axis="1 0 0" range="-1.57 1.57" actuatorfrcrange="-2.5 2.5"/>
      <geom type="mesh" rgba="0.752941 0.752941 0.752941 1" mesh="fr_hip_link"/>
      <body name="fr_thigh_link" pos="0.022055 -0.021 0.00041">
        <inertial pos="-0.0626115 -0.00685326 5.47714e-08" quat="0.503713 0.503724 0.496248 0.496259" mass="0.0357823" diaginertia="1.62922e-05 1.5657e-05 1.82581e-06"/>
        <joint name="fr_hip_pitch_joint" pos="0 0 0" axis="0 -1 0" range="0 3.14" actuatorfrcrange="-2.5 2.5"/>
        <geom type="mesh" rgba="0.752941 0.752941 0.752941 1" mesh="fr_thigh_link"/>
        <body name="fr_calf_link" pos="-0.13 5e-05 0">
          <inertial pos="0.0724501 -0.00768914 -0.0161896" quat="0.181537 0.744111 0.262615 0.586836" mass="0.0489997" diaginertia="3.66748e-05 3.59051e-05 5.09399e-06"/>
          <joint name="fr_knee_joint" pos="0 0 0" axis="0 -1 0" range="-3.14 0" actuatorfrcrange="-2.5 2.5"/>
          <geom type="mesh" rgba="0.752941 0.752941 0.752941 1" mesh="fr_calf_link"/>
        </body>
      </body>
    </body>
    <body name="fl_hip_link" pos="0.1034 0.0557689 -0.018465">
      <inertial pos="0.0319882 0.000410061 -0.0140991" quat="0.501243 0.501038 0.49882 0.498893" mass="0.108543" diaginertia="4.61468e-05 4.28245e-05 2.69788e-05"/>
      <joint name="fl_hip_roll_joint" pos="0 0 0" axis="1 0 0" range="-1.57 1.57" actuatorfrcrange="-2.5 2.5"/>
      <geom type="mesh" rgba="0.752941 0.752941 0.752941 1" mesh="fl_hip_link"/>
      <body name="fl_thigh_link" pos="0.021575 0.021 0">
        <inertial pos="-0.062611 0.0068533 -5.4771e-08" quat="0.496248 0.496259 0.503713 0.503724" mass="0.035782" diaginertia="1.62922e-05 1.5657e-05 1.82578e-06"/>
        <joint name="fl_hip_pitch_joint" pos="0 0 0" axis="0 1 0" range="-3.14 0" actuatorfrcrange="-2.5 2.5"/>
        <geom type="mesh" rgba="0.75294 0.75294 0.75294 1" mesh="fl_thigh_link"/>
        <body name="fl_calf_link" pos="-0.13 -5e-05 0">
          <inertial pos="0.0724809 0.00768626 -0.0162002" quat="-0.181543 0.74392 -0.262765 0.58701" mass="0.0489855" diaginertia="3.66302e-05 3.58563e-05 5.08653e-06"/>
          <joint name="fl_knee_joint" pos="0 0 0" axis="0 1 0" range="0 3.14" actuatorfrcrange="-2.5 2.5"/>
          <geom type="mesh" rgba="0.752941 0.752941 0.752941 1" mesh="fl_calf_link"/>
        </body>
      </body>
    </body>
    <body name="br_hip_link" pos="-0.1034 -0.0557689 -0.018465">
      <inertial pos="-0.0321355 -0.000410061 -0.0139732" quat="0.501038 0.501243 0.498893 0.49882" mass="0.108543" diaginertia="4.61468e-05 4.28245e-05 2.69788e-05"/>
      <joint name="br_hip_roll_joint" pos="0 0 0" axis="-1 0 0" range="-1.57 1.57" actuatorfrcrange="-2.5 2.5"/>
      <geom type="mesh" rgba="0.752941 0.752941 0.752941 1" mesh="br_hip_link"/>
      <body name="br_thigh_link" pos="-0.041945 -0.021 0.00041">
        <inertial pos="-0.0626115 -0.00685326 5.47714e-08" quat="0.503713 0.503724 0.496248 0.496259" mass="0.0357823" diaginertia="1.62922e-05 1.5657e-05 1.82581e-06"/>
        <joint name="br_hip_pitch_joint" pos="0 0 0" axis="0 -1 0" range="0 3.14" actuatorfrcrange="-2.5 2.5"/>
        <geom type="mesh" rgba="0.752941 0.752941 0.752941 1" mesh="br_thigh_link"/>
        <body name="br_calf_link" pos="-0.13 5e-05 0">
          <inertial pos="0.0724501 -0.00768914 -0.0161896" quat="0.181537 0.744111 0.262615 0.586836" mass="0.0489997" diaginertia="3.66748e-05 3.59051e-05 5.09399e-06"/>
          <joint name="br_knee_joint" pos="0 0 0" axis="0 -1 0" range="-3.14 0" actuatorfrcrange="-2.5 2.5"/>
          <geom type="mesh" rgba="0.752941 0.752941 0.752941 1" mesh="br_calf_link"/>
        </body>
      </body>
    </body>
    <body name="bl_hip_link" pos="-0.1034 0.055769 -0.018465">
      <inertial pos="-0.0319882 0.000429461 -0.0140006" quat="0.496046 0.501642 0.49853 0.503748" mass="0.108649" diaginertia="4.61686e-05 4.28729e-05 2.69799e-05"/>
      <joint name="bl_hip_roll_joint" pos="0 0 0" axis="-1 0 0" range="-1.57 1.57" actuatorfrcrange="-2.5 2.5"/>
      <geom type="mesh" rgba="0.752941 0.752941 0.752941 1" mesh="bl_hip_link"/>
      <body name="bl_thigh_link" pos="-0.041945 0.021 0.00041">
        <inertial pos="-0.0626115 0.00685326 -5.47714e-08" quat="0.496248 0.496259 0.503713 0.503724" mass="0.0357823" diaginertia="1.62922e-05 1.5657e-05 1.82581e-06"/>
        <joint name="bl_hip_pitch_joint" pos="0 0 0" axis="0 1 0" range="-3.14 0" actuatorfrcrange="-2.5 2.5"/>
        <geom type="mesh" rgba="0.752941 0.752941 0.752941 1" mesh="bl_thigh_link"/>
        <body name="bl_calf_link" pos="-0.13 -5e-05 0">
          <inertial pos="0.0724809 0.00768626 -0.0162002" quat="-0.181543 0.74392 -0.262765 0.58701" mass="0.0489855" diaginertia="3.66302e-05 3.58563e-05 5.08653e-06"/>
          <joint name="bl_knee_joint" pos="0 0 0" axis="0 1 0" range="0 3.14" actuatorfrcrange="-2.5 2.5"/>
          <geom type="mesh" rgba="0.752941 0.752941 0.752941 1" mesh="bl_calf_link"/>
        </body>
      </body>
    </body>
  </worldbody>
</mujoco>
